{
    "active_lock_reason": null,
    "assignee": null,
    "assignees": [],
    "author_association": "NONE",
    "body": "I wanted to build GMT from source. I looked at http://gmt.soest.hawaii.edu/projects/gmt/wiki/BuildingGMT#UbuntuDebian, but got\r\n\r\n> E: Unable to locate package libgdal1-dev\r\n\r\nInstalling only\r\n\r\n> sudo apt-get install subversion build-essential cmake libcurl4-gnutls-dev libnetcdf-dev libfftw3-dev libpcre3-dev liblapack-dev libblas-dev\r\n\r\nworked. I guessed that `libgdal-dev` was ment and installed it.\r\n\r\nThen I followed http://gmt.soest.hawaii.edu/projects/gmt/wiki/BuildingGMT#Building-GMT-from-source\r\n\r\nAlthough I set `export GMT_LIBRARY_PATH=$HOME/GitHub/gmt-dev/build/src` (where I built gmt-dev and where the libgmt.so is), I get the error\r\n\r\n## Full code/command that generated the error\r\n\r\n    >>> import gmt\r\n\r\n## Full error message\r\n\r\n```\r\n---------------------------------------------------------------------------\r\nGMTCLibError                              Traceback (most recent call last)\r\n<ipython-input-3-bc3c7e33fc1a> in <module>()\r\n----> 1 import gmt  # https://www.gmtpython.xyz/latest/install.html\r\n\r\n~/.local/lib/python3.6/site-packages/gmt/__init__.py in <module>()\r\n     15 \r\n     16 # Start our global modern mode session\r\n---> 17 _begin()\r\n     18 # Tell Python to run _end when shutting down\r\n     19 _atexit.register(_end)\r\n\r\n~/.local/lib/python3.6/site-packages/gmt/session_management.py in begin()\r\n     15     \"\"\"\r\n     16     prefix = 'gmt-python-session'\r\n---> 17     with LibGMT() as lib:\r\n     18         lib.call_module('begin', prefix)\r\n     19 \r\n\r\n~/.local/lib/python3.6/site-packages/gmt/clib/core.py in __init__(self)\r\n    155 \r\n    156     def __init__(self):\r\n--> 157         self._libgmt = load_libgmt()\r\n    158         self._session_id = None\r\n    159         self._session_name = 'gmt-python-session'\r\n\r\n~/.local/lib/python3.6/site-packages/gmt/clib/core.py in load_libgmt(libname)\r\n    122     try:\r\n    123         libgmt = ctypes.CDLL('.'.join([libname, clib_extension()]))\r\n--> 124         check_libgmt(libgmt)\r\n    125     except OSError as err:\r\n    126         msg = ' '.join([\r\n\r\n~/.local/lib/python3.6/site-packages/gmt/clib/core.py in check_libgmt(libgmt)\r\n     69                 \"Couldn't access function GMT_{}.\".format(func),\r\n     70             ])\r\n---> 71             raise GMTCLibError(msg)\r\n     72 \r\n     73 \r\n\r\nGMTCLibError: Error loading libgmt. Couldn't access function GMT_Get_Enum.\r\n```\r\n\r\n## System information\r\n\r\n* Operating system: Ubuntu 18.04\r\n* Python installation (Anaconda, system, ETS):\r\n* Version of GMT/Python: 3.6.5\r\n* How you installed GMT/Python: pre-installed python\r\n\r\n\r\n*If this is a **question or feature request**, delete the above lines and instead:*\r\n\r\n* Describe the feature you desire in as much detail as possible:\r\n\r\n* Are you willing to try to implement and maintain this feature? \r\n  We'll help you through the process.\r\n",
    "closed_at": "2019-02-07T15:58:15Z",
    "closed_by": {
        "avatar_url": "https://avatars.githubusercontent.com/u/3974108?v=4",
        "events_url": "https://api.github.com/users/seisman/events{/privacy}",
        "followers_url": "https://api.github.com/users/seisman/followers",
        "following_url": "https://api.github.com/users/seisman/following{/other_user}",
        "gists_url": "https://api.github.com/users/seisman/gists{/gist_id}",
        "gravatar_id": "",
        "html_url": "https://github.com/seisman",
        "id": 3974108,
        "login": "seisman",
        "node_id": "MDQ6VXNlcjM5NzQxMDg=",
        "organizations_url": "https://api.github.com/users/seisman/orgs",
        "received_events_url": "https://api.github.com/users/seisman/received_events",
        "repos_url": "https://api.github.com/users/seisman/repos",
        "site_admin": false,
        "starred_url": "https://api.github.com/users/seisman/starred{/owner}{/repo}",
        "subscriptions_url": "https://api.github.com/users/seisman/subscriptions",
        "type": "User",
        "url": "https://api.github.com/users/seisman"
    },
    "comments": 5,
    "comments_content": [
        {
            "author_association": "MEMBER",
            "body": "Hi @MartinThoma :wave:, thanks for reporting this issue! I think you're the first one to try to do this :)\r\n\r\nThat's a strange error. It's happening when we check if the GMT library has some common functions: https://github.com/GenericMappingTools/gmt-python/blob/master/gmt/clib/loading.py#L137\r\n\r\nI've actually never see this fail before. Could you please post the output of `gmt --version`?  I'll try to reproduce your error on my machine.",
            "created_at": "2018-07-24T05:11:35Z",
            "html_url": "https://github.com/GenericMappingTools/pygmt/issues/215#issuecomment-407283213",
            "id": 407283213,
            "issue_url": "https://api.github.com/repos/GenericMappingTools/pygmt/issues/215",
            "node_id": "MDEyOklzc3VlQ29tbWVudDQwNzI4MzIxMw==",
            "performed_via_github_app": null,
            "reactions": {
                "+1": 0,
                "-1": 0,
                "confused": 0,
                "eyes": 0,
                "heart": 0,
                "hooray": 0,
                "laugh": 0,
                "rocket": 0,
                "total_count": 0,
                "url": "https://api.github.com/repos/GenericMappingTools/pygmt/issues/comments/407283213/reactions"
            },
            "updated_at": "2018-07-24T05:11:35Z",
            "url": "https://api.github.com/repos/GenericMappingTools/pygmt/issues/comments/407283213",
            "user": {
                "avatar_url": "https://avatars.githubusercontent.com/u/290082?v=4",
                "events_url": "https://api.github.com/users/leouieda/events{/privacy}",
                "followers_url": "https://api.github.com/users/leouieda/followers",
                "following_url": "https://api.github.com/users/leouieda/following{/other_user}",
                "gists_url": "https://api.github.com/users/leouieda/gists{/gist_id}",
                "gravatar_id": "",
                "html_url": "https://github.com/leouieda",
                "id": 290082,
                "login": "leouieda",
                "node_id": "MDQ6VXNlcjI5MDA4Mg==",
                "organizations_url": "https://api.github.com/users/leouieda/orgs",
                "received_events_url": "https://api.github.com/users/leouieda/received_events",
                "repos_url": "https://api.github.com/users/leouieda/repos",
                "site_admin": false,
                "starred_url": "https://api.github.com/users/leouieda/starred{/owner}{/repo}",
                "subscriptions_url": "https://api.github.com/users/leouieda/subscriptions",
                "type": "User",
                "url": "https://api.github.com/users/leouieda"
            }
        },
        {
            "author_association": "NONE",
            "body": "I get a similar error message like this, when I follow the exact instructions from: https://www.gmtpython.xyz/latest/install.html.",
            "created_at": "2018-08-08T12:34:52Z",
            "html_url": "https://github.com/GenericMappingTools/pygmt/issues/215#issuecomment-411389368",
            "id": 411389368,
            "issue_url": "https://api.github.com/repos/GenericMappingTools/pygmt/issues/215",
            "node_id": "MDEyOklzc3VlQ29tbWVudDQxMTM4OTM2OA==",
            "performed_via_github_app": null,
            "reactions": {
                "+1": 0,
                "-1": 0,
                "confused": 0,
                "eyes": 0,
                "heart": 0,
                "hooray": 0,
                "laugh": 0,
                "rocket": 0,
                "total_count": 0,
                "url": "https://api.github.com/repos/GenericMappingTools/pygmt/issues/comments/411389368/reactions"
            },
            "updated_at": "2018-08-08T12:35:14Z",
            "url": "https://api.github.com/repos/GenericMappingTools/pygmt/issues/comments/411389368",
            "user": {
                "avatar_url": "https://avatars.githubusercontent.com/u/5647458?v=4",
                "events_url": "https://api.github.com/users/janjaapmeijer/events{/privacy}",
                "followers_url": "https://api.github.com/users/janjaapmeijer/followers",
                "following_url": "https://api.github.com/users/janjaapmeijer/following{/other_user}",
                "gists_url": "https://api.github.com/users/janjaapmeijer/gists{/gist_id}",
                "gravatar_id": "",
                "html_url": "https://github.com/janjaapmeijer",
                "id": 5647458,
                "login": "janjaapmeijer",
                "node_id": "MDQ6VXNlcjU2NDc0NTg=",
                "organizations_url": "https://api.github.com/users/janjaapmeijer/orgs",
                "received_events_url": "https://api.github.com/users/janjaapmeijer/received_events",
                "repos_url": "https://api.github.com/users/janjaapmeijer/repos",
                "site_admin": false,
                "starred_url": "https://api.github.com/users/janjaapmeijer/starred{/owner}{/repo}",
                "subscriptions_url": "https://api.github.com/users/janjaapmeijer/subscriptions",
                "type": "User",
                "url": "https://api.github.com/users/janjaapmeijer"
            }
        },
        {
            "author_association": "CONTRIBUTOR",
            "body": "@MartinThoma @janjaapmeijer  I believe this may be due to same API change issue identified in #222, depending on revision built. Revision of gmt 6.0.0 after r20437 will not work without using the code proposed in pr #224. The timing is convenient, this issue was opened 19 days ago, which is 2 days after `r20437` was pushed. ",
            "created_at": "2018-08-09T06:03:04Z",
            "html_url": "https://github.com/GenericMappingTools/pygmt/issues/215#issuecomment-411646646",
            "id": 411646646,
            "issue_url": "https://api.github.com/repos/GenericMappingTools/pygmt/issues/215",
            "node_id": "MDEyOklzc3VlQ29tbWVudDQxMTY0NjY0Ng==",
            "performed_via_github_app": null,
            "reactions": {
                "+1": 1,
                "-1": 0,
                "confused": 0,
                "eyes": 0,
                "heart": 0,
                "hooray": 0,
                "laugh": 0,
                "rocket": 0,
                "total_count": 1,
                "url": "https://api.github.com/repos/GenericMappingTools/pygmt/issues/comments/411646646/reactions"
            },
            "updated_at": "2018-08-09T06:03:04Z",
            "url": "https://api.github.com/repos/GenericMappingTools/pygmt/issues/comments/411646646",
            "user": {
                "avatar_url": "https://avatars.githubusercontent.com/u/6558063?v=4",
                "events_url": "https://api.github.com/users/akshmakov/events{/privacy}",
                "followers_url": "https://api.github.com/users/akshmakov/followers",
                "following_url": "https://api.github.com/users/akshmakov/following{/other_user}",
                "gists_url": "https://api.github.com/users/akshmakov/gists{/gist_id}",
                "gravatar_id": "",
                "html_url": "https://github.com/akshmakov",
                "id": 6558063,
                "login": "akshmakov",
                "node_id": "MDQ6VXNlcjY1NTgwNjM=",
                "organizations_url": "https://api.github.com/users/akshmakov/orgs",
                "received_events_url": "https://api.github.com/users/akshmakov/received_events",
                "repos_url": "https://api.github.com/users/akshmakov/repos",
                "site_admin": false,
                "starred_url": "https://api.github.com/users/akshmakov/starred{/owner}{/repo}",
                "subscriptions_url": "https://api.github.com/users/akshmakov/subscriptions",
                "type": "User",
                "url": "https://api.github.com/users/akshmakov"
            }
        },
        {
            "author_association": "NONE",
            "body": "I am getting the same error.\r\n\r\nI am using windows linux subsystem. ubuntu 18 from windows store\r\n\r\ndistribution anaconda python 3.6.5\r\ngmt is installed using pip.\r\n\r\n`pip install gmt-python`\r\n\r\nconda installation also gives the same error.\r\n\r\n```\r\nTraceback (most recent call last):\r\n  File \"/home/khalil/anaconda3/lib/python3.6/site-packages/gmt/clib/core.py\", line 123, in load_libgmt\r\n    libgmt = ctypes.CDLL('.'.join([libname, clib_extension()]))\r\n  File \"/home/khalil/anaconda3/lib/python3.6/ctypes/__init__.py\", line 348, in __init__\r\n    self._handle = _dlopen(self._name, mode)\r\nOSError: libgmt.so: cannot open shared object file: No such file or directory\r\n\r\nDuring handling of the above exception, another exception occurred:\r\n\r\nTraceback (most recent call last):\r\n  File \"/mnt/c/Users/kalho/Desktop/ubuntu/Untitled.py\", line 1, in <module>\r\n    import gmt\r\n  File \"/home/khalil/anaconda3/lib/python3.6/site-packages/gmt/__init__.py\", line 17, in <module>\r\n    _begin()\r\n  File \"/home/khalil/anaconda3/lib/python3.6/site-packages/gmt/session_management.py\", line 17, in begin\r\n    with LibGMT() as lib:\r\n  File \"/home/khalil/anaconda3/lib/python3.6/site-packages/gmt/clib/core.py\", line 157, in __init__\r\n    self._libgmt = load_libgmt()\r\n  File \"/home/khalil/anaconda3/lib/python3.6/site-packages/gmt/clib/core.py\", line 132, in load_libgmt\r\n    raise GMTCLibNotFoundError(msg)\r\ngmt.exceptions.GMTCLibNotFoundError: Couldn't find the GMT shared library 'libgmt'. Have you tried setting the LD_LIBRARY_PATH environment variable?\r\nOriginal error message:\r\n\r\n    libgmt.so: cannot open shared object file: No such file or directory\r\n```\r\n\r\nI installed libgmt-dev: sudo apt install libgmt-dev\r\n\r\n\r\n```\r\n(base) khalil@khooti:~$ /home/khalil/anaconda3/bin/python /mnt/c/Users/kalho/Desktop/ubuntu/Untitled.py\r\nTraceback (most recent call last):\r\n  File \"/mnt/c/Users/kalho/Desktop/ubuntu/Untitled.py\", line 1, in <module>\r\n    import gmt\r\n  File \"/home/khalil/anaconda3/lib/python3.6/site-packages/gmt/__init__.py\", line 17, in <module>\r\n    _begin()\r\n  File \"/home/khalil/anaconda3/lib/python3.6/site-packages/gmt/session_management.py\", line 17, in begin\r\n    with LibGMT() as lib:\r\n  File \"/home/khalil/anaconda3/lib/python3.6/site-packages/gmt/clib/core.py\", line 157, in __init__\r\n    self._libgmt = load_libgmt()\r\n  File \"/home/khalil/anaconda3/lib/python3.6/site-packages/gmt/clib/core.py\", line 124, in load_libgmt\r\n    check_libgmt(libgmt)\r\n  File \"/home/khalil/anaconda3/lib/python3.6/site-packages/gmt/clib/core.py\", line 71, in check_libgmt\r\n    raise GMTCLibError(msg)\r\ngmt.exceptions.GMTCLibError: Error loading libgmt. Couldn't access function GMT_Get_Enum.\r\n```",
            "created_at": "2018-08-28T20:40:38Z",
            "html_url": "https://github.com/GenericMappingTools/pygmt/issues/215#issuecomment-416732900",
            "id": 416732900,
            "issue_url": "https://api.github.com/repos/GenericMappingTools/pygmt/issues/215",
            "node_id": "MDEyOklzc3VlQ29tbWVudDQxNjczMjkwMA==",
            "performed_via_github_app": null,
            "reactions": {
                "+1": 0,
                "-1": 0,
                "confused": 0,
                "eyes": 0,
                "heart": 0,
                "hooray": 0,
                "laugh": 0,
                "rocket": 0,
                "total_count": 0,
                "url": "https://api.github.com/repos/GenericMappingTools/pygmt/issues/comments/416732900/reactions"
            },
            "updated_at": "2018-08-28T20:52:11Z",
            "url": "https://api.github.com/repos/GenericMappingTools/pygmt/issues/comments/416732900",
            "user": {
                "avatar_url": "https://avatars.githubusercontent.com/u/22060413?v=4",
                "events_url": "https://api.github.com/users/Khalilsqu/events{/privacy}",
                "followers_url": "https://api.github.com/users/Khalilsqu/followers",
                "following_url": "https://api.github.com/users/Khalilsqu/following{/other_user}",
                "gists_url": "https://api.github.com/users/Khalilsqu/gists{/gist_id}",
                "gravatar_id": "",
                "html_url": "https://github.com/Khalilsqu",
                "id": 22060413,
                "login": "Khalilsqu",
                "node_id": "MDQ6VXNlcjIyMDYwNDEz",
                "organizations_url": "https://api.github.com/users/Khalilsqu/orgs",
                "received_events_url": "https://api.github.com/users/Khalilsqu/received_events",
                "repos_url": "https://api.github.com/users/Khalilsqu/repos",
                "site_admin": false,
                "starred_url": "https://api.github.com/users/Khalilsqu/starred{/owner}{/repo}",
                "subscriptions_url": "https://api.github.com/users/Khalilsqu/subscriptions",
                "type": "User",
                "url": "https://api.github.com/users/Khalilsqu"
            }
        },
        {
            "author_association": "MEMBER",
            "body": "I think this issue can be closed, since our travis tests now build GMT from source and pass.",
            "created_at": "2019-02-07T15:58:15Z",
            "html_url": "https://github.com/GenericMappingTools/pygmt/issues/215#issuecomment-461484016",
            "id": 461484016,
            "issue_url": "https://api.github.com/repos/GenericMappingTools/pygmt/issues/215",
            "node_id": "MDEyOklzc3VlQ29tbWVudDQ2MTQ4NDAxNg==",
            "performed_via_github_app": null,
            "reactions": {
                "+1": 1,
                "-1": 0,
                "confused": 0,
                "eyes": 0,
                "heart": 0,
                "hooray": 0,
                "laugh": 0,
                "rocket": 0,
                "total_count": 1,
                "url": "https://api.github.com/repos/GenericMappingTools/pygmt/issues/comments/461484016/reactions"
            },
            "updated_at": "2019-02-07T15:58:15Z",
            "url": "https://api.github.com/repos/GenericMappingTools/pygmt/issues/comments/461484016",
            "user": {
                "avatar_url": "https://avatars.githubusercontent.com/u/3974108?v=4",
                "events_url": "https://api.github.com/users/seisman/events{/privacy}",
                "followers_url": "https://api.github.com/users/seisman/followers",
                "following_url": "https://api.github.com/users/seisman/following{/other_user}",
                "gists_url": "https://api.github.com/users/seisman/gists{/gist_id}",
                "gravatar_id": "",
                "html_url": "https://github.com/seisman",
                "id": 3974108,
                "login": "seisman",
                "node_id": "MDQ6VXNlcjM5NzQxMDg=",
                "organizations_url": "https://api.github.com/users/seisman/orgs",
                "received_events_url": "https://api.github.com/users/seisman/received_events",
                "repos_url": "https://api.github.com/users/seisman/repos",
                "site_admin": false,
                "starred_url": "https://api.github.com/users/seisman/starred{/owner}{/repo}",
                "subscriptions_url": "https://api.github.com/users/seisman/subscriptions",
                "type": "User",
                "url": "https://api.github.com/users/seisman"
            }
        }
    ],
    "comments_url": "https://api.github.com/repos/GenericMappingTools/pygmt/issues/215/comments",
    "created_at": "2018-07-20T21:33:39Z",
    "events_url": "https://api.github.com/repos/GenericMappingTools/pygmt/issues/215/events",
    "html_url": "https://github.com/GenericMappingTools/pygmt/issues/215",
    "id": 343253974,
    "labels": [
        {
            "color": "ee0701",
            "default": true,
            "description": "Something isn't working",
            "id": 563309827,
            "name": "bug",
            "node_id": "MDU6TGFiZWw1NjMzMDk4Mjc=",
            "url": "https://api.github.com/repos/GenericMappingTools/pygmt/labels/bug"
        }
    ],
    "labels_url": "https://api.github.com/repos/GenericMappingTools/pygmt/issues/215/labels{/name}",
    "locked": false,
    "milestone": null,
    "node_id": "MDU6SXNzdWUzNDMyNTM5NzQ=",
    "number": 215,
    "performed_via_github_app": null,
    "reactions": {
        "+1": 0,
        "-1": 0,
        "confused": 0,
        "eyes": 0,
        "heart": 0,
        "hooray": 0,
        "laugh": 0,
        "rocket": 0,
        "total_count": 0,
        "url": "https://api.github.com/repos/GenericMappingTools/pygmt/issues/215/reactions"
    },
    "repository_url": "https://api.github.com/repos/GenericMappingTools/pygmt",
    "state": "closed",
    "state_reason": "completed",
    "timeline_url": "https://api.github.com/repos/GenericMappingTools/pygmt/issues/215/timeline",
    "title": "GMT on Ubuntu 18.04",
    "updated_at": "2019-02-07T15:58:16Z",
    "url": "https://api.github.com/repos/GenericMappingTools/pygmt/issues/215",
    "user": {
        "avatar_url": "https://avatars.githubusercontent.com/u/1658117?v=4",
        "events_url": "https://api.github.com/users/MartinThoma/events{/privacy}",
        "followers_url": "https://api.github.com/users/MartinThoma/followers",
        "following_url": "https://api.github.com/users/MartinThoma/following{/other_user}",
        "gists_url": "https://api.github.com/users/MartinThoma/gists{/gist_id}",
        "gravatar_id": "",
        "html_url": "https://github.com/MartinThoma",
        "id": 1658117,
        "login": "MartinThoma",
        "node_id": "MDQ6VXNlcjE2NTgxMTc=",
        "organizations_url": "https://api.github.com/users/MartinThoma/orgs",
        "received_events_url": "https://api.github.com/users/MartinThoma/received_events",
        "repos_url": "https://api.github.com/users/MartinThoma/repos",
        "site_admin": false,
        "starred_url": "https://api.github.com/users/MartinThoma/starred{/owner}{/repo}",
        "subscriptions_url": "https://api.github.com/users/MartinThoma/subscriptions",
        "type": "User",
        "url": "https://api.github.com/users/MartinThoma"
    }
}