{
    "active_lock_reason": null,
    "assignee": null,
    "assignees": [],
    "author_association": "NONE",
    "body": "**Description of the problem**\r\n\r\nThe **Python Debug Console** of VsCode aborted when debug pyGMT.\r\n\r\n* Debug python file :heavy_multiplication_x:\r\n![image](https://user-images.githubusercontent.com/56864878/140943642-49a14b3a-0226-433d-9c7d-38b217b71d6d.png)\r\n\r\n* Run python file :heavy_check_mark:\r\n![image](https://user-images.githubusercontent.com/56864878/140944065-84257712-b81e-4b00-8e02-c2273d1ea58d.png)\r\n\r\n\r\n**Full code that generated the error**\r\n\r\n[one example](https://www.pygmt.org/latest/gallery/symbols/points.html#sphx-glr-gallery-symbols-points-py)\r\n```python\r\nimport numpy as np\r\nimport pygmt\r\n\r\n# Generate a random set of points to plot\r\nnp.random.seed(42)\r\nregion = [150, 240, -10, 60]\r\nx = np.random.uniform(region[0], region[1], 100)\r\ny = np.random.uniform(region[2], region[3], 100)\r\n\r\nfig = pygmt.Figure()\r\n# Create a 15 cm x 15 cm basemap with a Cartesian projection (X) using the\r\n# data region\r\nfig.basemap(region=region, projection=\"X15c\", frame=True)\r\n# Plot using inverted triangles (i) of 0.5 cm size\r\nfig.plot(x=x, y=y, style=\"i0.5c\", color=\"black\")\r\n# fig.show()\r\n```\r\n\r\n**Full error message**\r\n\r\n```\r\ndouble free or corruption (out)\r\n```\r\n\r\n**System information** \r\n\r\nPlease paste the output of `python -c \"import pygmt; pygmt.show_versions()\"`:\r\n\r\n```\r\nPyGMT information:\r\n  version: v0.4.1\r\nSystem information:\r\n  python: 3.9.7 | packaged by conda-forge | (default, Sep 29 2021, 19:20:46)  [GCC 9.4.0]\r\n  executable: /home/wxz/Program/miniconda3/envs/seismic/bin/python\r\n  machine: Linux-5.11.0-38-generic-x86_64-with-glibc2.31\r\nDependency information:\r\n  numpy: 1.21.2\r\n  pandas: 1.3.3\r\n  xarray: 0.19.0\r\n  netCDF4: 1.5.7\r\n  packaging: 21.0\r\n  ghostscript: 9.54.0\r\n  gmt: 6.2.0\r\nGMT library information:\r\n  binary dir: /home/wxz/Program/miniconda3/envs/seismic/bin\r\n  cores: 16\r\n  grid layout: rows\r\n  library path: /home/wxz/Program/miniconda3/envs/seismic/lib/libgmt.so\r\n  padding: 2\r\n  plugin dir: /home/wxz/Program/miniconda3/envs/seismic/lib/gmt/plugins\r\n  share dir: /home/wxz/Program/miniconda3/envs/seismic/share/gmt\r\n  version: 6.2.0\r\n```\r\n",
    "closed_at": "2021-11-12T08:53:56Z",
    "closed_by": {
        "avatar_url": "https://avatars.githubusercontent.com/u/56864878?v=4",
        "events_url": "https://api.github.com/users/WXZhao7/events{/privacy}",
        "followers_url": "https://api.github.com/users/WXZhao7/followers",
        "following_url": "https://api.github.com/users/WXZhao7/following{/other_user}",
        "gists_url": "https://api.github.com/users/WXZhao7/gists{/gist_id}",
        "gravatar_id": "",
        "html_url": "https://github.com/WXZhao7",
        "id": 56864878,
        "login": "WXZhao7",
        "node_id": "MDQ6VXNlcjU2ODY0ODc4",
        "organizations_url": "https://api.github.com/users/WXZhao7/orgs",
        "received_events_url": "https://api.github.com/users/WXZhao7/received_events",
        "repos_url": "https://api.github.com/users/WXZhao7/repos",
        "site_admin": false,
        "starred_url": "https://api.github.com/users/WXZhao7/starred{/owner}{/repo}",
        "subscriptions_url": "https://api.github.com/users/WXZhao7/subscriptions",
        "type": "User",
        "url": "https://api.github.com/users/WXZhao7"
    },
    "comments": 7,
    "comments_content": [
        {
            "author_association": "MEMBER",
            "body": "Hi @WXZhao7, I don't use VSCode, but I can't seem to reproduce the crash on my Linux machine. Let's see if someone who uses VSCode can try and see if this is an issue. In the meantime, have you tried deleting the conda environment and reinstalling from scratch?",
            "created_at": "2021-11-11T22:26:05Z",
            "html_url": "https://github.com/GenericMappingTools/pygmt/issues/1619#issuecomment-966669767",
            "id": 966669767,
            "issue_url": "https://api.github.com/repos/GenericMappingTools/pygmt/issues/1619",
            "node_id": "IC_kwDOBRZfO845njXH",
            "performed_via_github_app": null,
            "reactions": {
                "+1": 0,
                "-1": 0,
                "confused": 0,
                "eyes": 0,
                "heart": 0,
                "hooray": 0,
                "laugh": 0,
                "rocket": 0,
                "total_count": 0,
                "url": "https://api.github.com/repos/GenericMappingTools/pygmt/issues/comments/966669767/reactions"
            },
            "updated_at": "2021-11-11T22:26:17Z",
            "url": "https://api.github.com/repos/GenericMappingTools/pygmt/issues/comments/966669767",
            "user": {
                "avatar_url": "https://avatars.githubusercontent.com/u/23487320?v=4",
                "events_url": "https://api.github.com/users/weiji14/events{/privacy}",
                "followers_url": "https://api.github.com/users/weiji14/followers",
                "following_url": "https://api.github.com/users/weiji14/following{/other_user}",
                "gists_url": "https://api.github.com/users/weiji14/gists{/gist_id}",
                "gravatar_id": "",
                "html_url": "https://github.com/weiji14",
                "id": 23487320,
                "login": "weiji14",
                "node_id": "MDQ6VXNlcjIzNDg3MzIw",
                "organizations_url": "https://api.github.com/users/weiji14/orgs",
                "received_events_url": "https://api.github.com/users/weiji14/received_events",
                "repos_url": "https://api.github.com/users/weiji14/repos",
                "site_admin": false,
                "starred_url": "https://api.github.com/users/weiji14/starred{/owner}{/repo}",
                "subscriptions_url": "https://api.github.com/users/weiji14/subscriptions",
                "type": "User",
                "url": "https://api.github.com/users/weiji14"
            }
        },
        {
            "author_association": "MEMBER",
            "body": "I also can't reproduce your issue using VSCode Debug Console, and the dev PyGMT and GMT.",
            "created_at": "2021-11-12T06:20:28Z",
            "html_url": "https://github.com/GenericMappingTools/pygmt/issues/1619#issuecomment-966855468",
            "id": 966855468,
            "issue_url": "https://api.github.com/repos/GenericMappingTools/pygmt/issues/1619",
            "node_id": "IC_kwDOBRZfO845oQss",
            "performed_via_github_app": null,
            "reactions": {
                "+1": 0,
                "-1": 0,
                "confused": 0,
                "eyes": 0,
                "heart": 0,
                "hooray": 0,
                "laugh": 0,
                "rocket": 0,
                "total_count": 0,
                "url": "https://api.github.com/repos/GenericMappingTools/pygmt/issues/comments/966855468/reactions"
            },
            "updated_at": "2021-11-12T06:20:28Z",
            "url": "https://api.github.com/repos/GenericMappingTools/pygmt/issues/comments/966855468",
            "user": {
                "avatar_url": "https://avatars.githubusercontent.com/u/3974108?v=4",
                "events_url": "https://api.github.com/users/seisman/events{/privacy}",
                "followers_url": "https://api.github.com/users/seisman/followers",
                "following_url": "https://api.github.com/users/seisman/following{/other_user}",
                "gists_url": "https://api.github.com/users/seisman/gists{/gist_id}",
                "gravatar_id": "",
                "html_url": "https://github.com/seisman",
                "id": 3974108,
                "login": "seisman",
                "node_id": "MDQ6VXNlcjM5NzQxMDg=",
                "organizations_url": "https://api.github.com/users/seisman/orgs",
                "received_events_url": "https://api.github.com/users/seisman/received_events",
                "repos_url": "https://api.github.com/users/seisman/repos",
                "site_admin": false,
                "starred_url": "https://api.github.com/users/seisman/starred{/owner}{/repo}",
                "subscriptions_url": "https://api.github.com/users/seisman/subscriptions",
                "type": "User",
                "url": "https://api.github.com/users/seisman"
            }
        },
        {
            "author_association": "NONE",
            "body": "> I also can't reproduce your issue using VSCode Debug Console, and the dev PyGMT and GMT.\r\n\r\nI can debug pygmt with VScode, but the debugger can't exit correctly. I reproduce it as below:\r\n\r\n## Part 1. recreate environment\r\n\r\n* step 1, recreate conda env.\r\n```shell\r\nconda remove -n pygmt --all\r\nconda create --name pygmt --channel conda-forge pygmt\r\n```\r\n* step 2, install VScode insider version (avoid the influence from VScode setting)\r\n```shell\r\nsudo dpkg -i code-insiders_1.63.0-1636638160_amd64.deb\r\n```\r\n\r\n* step 3, install python extension in vscode\r\n```\r\next install ms-python.python\r\n```\r\n\r\n* step 4, add `\"terminal.integrated.inheritEnv\": false,` to settings.json of VScode. (avoid the influence from inherit env.)\r\n\r\n**Now a new enviroment is built.**\r\n\r\n![image](https://user-images.githubusercontent.com/56864878/141425744-76ab29bb-9531-4c7b-88b8-74a2789eec31.png)\r\n\r\n## Part 2, reproduce the issue\r\n\r\n* step 1, add `print(\">>>> done\")` at end of test code\r\n```python\r\nimport numpy as np\r\nimport pygmt\r\n\r\n\r\n# Generate a random set of points to plot\r\nnp.random.seed(42)\r\nregion = [150, 240, -10, 60]\r\nx = np.random.uniform(region[0], region[1], 100)\r\ny = np.random.uniform(region[2], region[3], 100)\r\n\r\nfig = pygmt.Figure()\r\n# Create a 15 cm x 15 cm basemap with a Cartesian projection (X) using the\r\n# data region\r\nfig.basemap(region=region, projection=\"X15c\", frame=True)\r\n# Plot using inverted triangles (i) of 0.5 cm size\r\nfig.plot(x=x, y=y, style=\"i0.5c\", color=\"black\")\r\n# fig.show()\r\nprint(\">>>> done\")\r\n```\r\n\r\n* step 2, click `Run and Debug` and select `Debug the currently active python file`\r\n\r\n![image](https://user-images.githubusercontent.com/56864878/141428118-f8b15798-dc1c-4b25-88f7-b13d1a1c0c7f.png)\r\n\r\n* step 3, I meet the same problem again\r\n\r\n![image](https://user-images.githubusercontent.com/56864878/141428520-923355ae-02f2-4429-a295-a7680e0440c7.png)\r\n\r\n* step 4, run the code in terminal\r\n\r\n![image](https://user-images.githubusercontent.com/56864878/141429169-efb04fde-cdaf-4a5c-9502-52d3cacd0772.png)\r\n\r\n I will try to reproduce it in VMware.\r\n",
            "created_at": "2021-11-12T08:10:57Z",
            "html_url": "https://github.com/GenericMappingTools/pygmt/issues/1619#issuecomment-966905566",
            "id": 966905566,
            "issue_url": "https://api.github.com/repos/GenericMappingTools/pygmt/issues/1619",
            "node_id": "IC_kwDOBRZfO845oc7e",
            "performed_via_github_app": null,
            "reactions": {
                "+1": 0,
                "-1": 0,
                "confused": 0,
                "eyes": 0,
                "heart": 0,
                "hooray": 0,
                "laugh": 0,
                "rocket": 0,
                "total_count": 0,
                "url": "https://api.github.com/repos/GenericMappingTools/pygmt/issues/comments/966905566/reactions"
            },
            "updated_at": "2021-11-12T08:10:57Z",
            "url": "https://api.github.com/repos/GenericMappingTools/pygmt/issues/comments/966905566",
            "user": {
                "avatar_url": "https://avatars.githubusercontent.com/u/56864878?v=4",
                "events_url": "https://api.github.com/users/WXZhao7/events{/privacy}",
                "followers_url": "https://api.github.com/users/WXZhao7/followers",
                "following_url": "https://api.github.com/users/WXZhao7/following{/other_user}",
                "gists_url": "https://api.github.com/users/WXZhao7/gists{/gist_id}",
                "gravatar_id": "",
                "html_url": "https://github.com/WXZhao7",
                "id": 56864878,
                "login": "WXZhao7",
                "node_id": "MDQ6VXNlcjU2ODY0ODc4",
                "organizations_url": "https://api.github.com/users/WXZhao7/orgs",
                "received_events_url": "https://api.github.com/users/WXZhao7/received_events",
                "repos_url": "https://api.github.com/users/WXZhao7/repos",
                "site_admin": false,
                "starred_url": "https://api.github.com/users/WXZhao7/starred{/owner}{/repo}",
                "subscriptions_url": "https://api.github.com/users/WXZhao7/subscriptions",
                "type": "User",
                "url": "https://api.github.com/users/WXZhao7"
            }
        },
        {
            "author_association": "NONE",
            "body": "Oh, I can't reproduce it in the virtual machine with same OS and kernel!\r\nMay be I have to reinstall system :sob: \r\n\r\n![image](https://user-images.githubusercontent.com/56864878/141438268-6139345f-e555-446c-a0cb-6143cdb28356.png)\r\n",
            "created_at": "2021-11-12T08:53:56Z",
            "html_url": "https://github.com/GenericMappingTools/pygmt/issues/1619#issuecomment-966930428",
            "id": 966930428,
            "issue_url": "https://api.github.com/repos/GenericMappingTools/pygmt/issues/1619",
            "node_id": "IC_kwDOBRZfO845oi_8",
            "performed_via_github_app": null,
            "reactions": {
                "+1": 0,
                "-1": 0,
                "confused": 0,
                "eyes": 0,
                "heart": 0,
                "hooray": 0,
                "laugh": 0,
                "rocket": 0,
                "total_count": 0,
                "url": "https://api.github.com/repos/GenericMappingTools/pygmt/issues/comments/966930428/reactions"
            },
            "updated_at": "2021-11-12T08:53:56Z",
            "url": "https://api.github.com/repos/GenericMappingTools/pygmt/issues/comments/966930428",
            "user": {
                "avatar_url": "https://avatars.githubusercontent.com/u/56864878?v=4",
                "events_url": "https://api.github.com/users/WXZhao7/events{/privacy}",
                "followers_url": "https://api.github.com/users/WXZhao7/followers",
                "following_url": "https://api.github.com/users/WXZhao7/following{/other_user}",
                "gists_url": "https://api.github.com/users/WXZhao7/gists{/gist_id}",
                "gravatar_id": "",
                "html_url": "https://github.com/WXZhao7",
                "id": 56864878,
                "login": "WXZhao7",
                "node_id": "MDQ6VXNlcjU2ODY0ODc4",
                "organizations_url": "https://api.github.com/users/WXZhao7/orgs",
                "received_events_url": "https://api.github.com/users/WXZhao7/received_events",
                "repos_url": "https://api.github.com/users/WXZhao7/repos",
                "site_admin": false,
                "starred_url": "https://api.github.com/users/WXZhao7/starred{/owner}{/repo}",
                "subscriptions_url": "https://api.github.com/users/WXZhao7/subscriptions",
                "type": "User",
                "url": "https://api.github.com/users/WXZhao7"
            }
        },
        {
            "author_association": "MEMBER",
            "body": "Maybe try doing a `gmt clear all`, and then `conda clean --all` after `conda env remove -n pygmt`, sometimes things get corrupted in the conda virtual environment :shrug:",
            "created_at": "2021-11-12T08:59:17Z",
            "html_url": "https://github.com/GenericMappingTools/pygmt/issues/1619#issuecomment-966933642",
            "id": 966933642,
            "issue_url": "https://api.github.com/repos/GenericMappingTools/pygmt/issues/1619",
            "node_id": "IC_kwDOBRZfO845ojyK",
            "performed_via_github_app": null,
            "reactions": {
                "+1": 0,
                "-1": 0,
                "confused": 0,
                "eyes": 0,
                "heart": 0,
                "hooray": 0,
                "laugh": 0,
                "rocket": 0,
                "total_count": 0,
                "url": "https://api.github.com/repos/GenericMappingTools/pygmt/issues/comments/966933642/reactions"
            },
            "updated_at": "2021-11-12T08:59:33Z",
            "url": "https://api.github.com/repos/GenericMappingTools/pygmt/issues/comments/966933642",
            "user": {
                "avatar_url": "https://avatars.githubusercontent.com/u/23487320?v=4",
                "events_url": "https://api.github.com/users/weiji14/events{/privacy}",
                "followers_url": "https://api.github.com/users/weiji14/followers",
                "following_url": "https://api.github.com/users/weiji14/following{/other_user}",
                "gists_url": "https://api.github.com/users/weiji14/gists{/gist_id}",
                "gravatar_id": "",
                "html_url": "https://github.com/weiji14",
                "id": 23487320,
                "login": "weiji14",
                "node_id": "MDQ6VXNlcjIzNDg3MzIw",
                "organizations_url": "https://api.github.com/users/weiji14/orgs",
                "received_events_url": "https://api.github.com/users/weiji14/received_events",
                "repos_url": "https://api.github.com/users/weiji14/repos",
                "site_admin": false,
                "starred_url": "https://api.github.com/users/weiji14/starred{/owner}{/repo}",
                "subscriptions_url": "https://api.github.com/users/weiji14/subscriptions",
                "type": "User",
                "url": "https://api.github.com/users/weiji14"
            }
        },
        {
            "author_association": "NONE",
            "body": "> Maybe try doing a `gmt clear all`, and then `conda clean --all` after `conda env remove -n pygmt`, sometimes things get corrupted in the conda virtual environment shrug\r\n\r\nI find the source of this problem----zsh!!! :anger: \r\nThis issue will disappear if I change the system shell to bash. I guess that may associate with the system environment. I will try to fix it.\r\nThanks for your help! @seisman @weiji14 \r\n",
            "created_at": "2021-11-12T09:11:27Z",
            "html_url": "https://github.com/GenericMappingTools/pygmt/issues/1619#issuecomment-966941546",
            "id": 966941546,
            "issue_url": "https://api.github.com/repos/GenericMappingTools/pygmt/issues/1619",
            "node_id": "IC_kwDOBRZfO845oltq",
            "performed_via_github_app": null,
            "reactions": {
                "+1": 0,
                "-1": 0,
                "confused": 0,
                "eyes": 0,
                "heart": 0,
                "hooray": 0,
                "laugh": 0,
                "rocket": 0,
                "total_count": 0,
                "url": "https://api.github.com/repos/GenericMappingTools/pygmt/issues/comments/966941546/reactions"
            },
            "updated_at": "2021-11-12T09:11:27Z",
            "url": "https://api.github.com/repos/GenericMappingTools/pygmt/issues/comments/966941546",
            "user": {
                "avatar_url": "https://avatars.githubusercontent.com/u/56864878?v=4",
                "events_url": "https://api.github.com/users/WXZhao7/events{/privacy}",
                "followers_url": "https://api.github.com/users/WXZhao7/followers",
                "following_url": "https://api.github.com/users/WXZhao7/following{/other_user}",
                "gists_url": "https://api.github.com/users/WXZhao7/gists{/gist_id}",
                "gravatar_id": "",
                "html_url": "https://github.com/WXZhao7",
                "id": 56864878,
                "login": "WXZhao7",
                "node_id": "MDQ6VXNlcjU2ODY0ODc4",
                "organizations_url": "https://api.github.com/users/WXZhao7/orgs",
                "received_events_url": "https://api.github.com/users/WXZhao7/received_events",
                "repos_url": "https://api.github.com/users/WXZhao7/repos",
                "site_admin": false,
                "starred_url": "https://api.github.com/users/WXZhao7/starred{/owner}{/repo}",
                "subscriptions_url": "https://api.github.com/users/WXZhao7/subscriptions",
                "type": "User",
                "url": "https://api.github.com/users/WXZhao7"
            }
        },
        {
            "author_association": "NONE",
            "body": "The conda initialization caused the `double free or corruption (out)`. I delete it from my `.bashrc` to solve the problem.\r\n```shell\r\n# >>> conda initialize >>>\r\n# !! Contents within this block are managed by 'conda init' !!\r\n__conda_setup=\"$('/home/wxz/Program/miniconda3/bin/conda' 'shell.zsh' 'hook' 2> /dev/null)\"\r\nif [ $? -eq 0 ]; then\r\n    eval \"$__conda_setup\"\r\nelse\r\n    if [ -f \"/home/wxz/Program/miniconda3/etc/profile.d/conda.sh\" ]; then\r\n        . \"/home/wxz/Program/miniconda3/etc/profile.d/conda.sh\"\r\n    else\r\n        export PATH=\"/home/wxz/Program/miniconda3/bin:$PATH\"\r\n    fi\r\nfi\r\nunset __conda_setup\r\n# <<< conda initialize <<<\r\n```",
            "created_at": "2021-11-12T13:17:19Z",
            "html_url": "https://github.com/GenericMappingTools/pygmt/issues/1619#issuecomment-967111640",
            "id": 967111640,
            "issue_url": "https://api.github.com/repos/GenericMappingTools/pygmt/issues/1619",
            "node_id": "IC_kwDOBRZfO845pPPY",
            "performed_via_github_app": null,
            "reactions": {
                "+1": 0,
                "-1": 0,
                "confused": 0,
                "eyes": 0,
                "heart": 0,
                "hooray": 0,
                "laugh": 0,
                "rocket": 0,
                "total_count": 0,
                "url": "https://api.github.com/repos/GenericMappingTools/pygmt/issues/comments/967111640/reactions"
            },
            "updated_at": "2021-11-12T13:17:19Z",
            "url": "https://api.github.com/repos/GenericMappingTools/pygmt/issues/comments/967111640",
            "user": {
                "avatar_url": "https://avatars.githubusercontent.com/u/56864878?v=4",
                "events_url": "https://api.github.com/users/WXZhao7/events{/privacy}",
                "followers_url": "https://api.github.com/users/WXZhao7/followers",
                "following_url": "https://api.github.com/users/WXZhao7/following{/other_user}",
                "gists_url": "https://api.github.com/users/WXZhao7/gists{/gist_id}",
                "gravatar_id": "",
                "html_url": "https://github.com/WXZhao7",
                "id": 56864878,
                "login": "WXZhao7",
                "node_id": "MDQ6VXNlcjU2ODY0ODc4",
                "organizations_url": "https://api.github.com/users/WXZhao7/orgs",
                "received_events_url": "https://api.github.com/users/WXZhao7/received_events",
                "repos_url": "https://api.github.com/users/WXZhao7/repos",
                "site_admin": false,
                "starred_url": "https://api.github.com/users/WXZhao7/starred{/owner}{/repo}",
                "subscriptions_url": "https://api.github.com/users/WXZhao7/subscriptions",
                "type": "User",
                "url": "https://api.github.com/users/WXZhao7"
            }
        }
    ],
    "comments_url": "https://api.github.com/repos/GenericMappingTools/pygmt/issues/1619/comments",
    "created_at": "2021-11-09T14:49:08Z",
    "events_url": "https://api.github.com/repos/GenericMappingTools/pygmt/issues/1619/events",
    "html_url": "https://github.com/GenericMappingTools/pygmt/issues/1619",
    "id": 1048695731,
    "labels": [
        {
            "color": "ee0701",
            "default": true,
            "description": "Something isn't working",
            "id": 563309827,
            "name": "bug",
            "node_id": "MDU6TGFiZWw1NjMzMDk4Mjc=",
            "url": "https://api.github.com/repos/GenericMappingTools/pygmt/labels/bug"
        }
    ],
    "labels_url": "https://api.github.com/repos/GenericMappingTools/pygmt/issues/1619/labels{/name}",
    "locked": false,
    "milestone": null,
    "node_id": "I_kwDOBRZfO84-gdOz",
    "number": 1619,
    "performed_via_github_app": null,
    "reactions": {
        "+1": 0,
        "-1": 0,
        "confused": 0,
        "eyes": 0,
        "heart": 0,
        "hooray": 0,
        "laugh": 0,
        "rocket": 0,
        "total_count": 0,
        "url": "https://api.github.com/repos/GenericMappingTools/pygmt/issues/1619/reactions"
    },
    "repository_url": "https://api.github.com/repos/GenericMappingTools/pygmt",
    "state": "closed",
    "state_reason": "completed",
    "timeline_url": "https://api.github.com/repos/GenericMappingTools/pygmt/issues/1619/timeline",
    "title": "'double free or corruption (out)' occurred in Python Debug Console of VsCode ",
    "updated_at": "2021-11-12T13:17:19Z",
    "url": "https://api.github.com/repos/GenericMappingTools/pygmt/issues/1619",
    "user": {
        "avatar_url": "https://avatars.githubusercontent.com/u/56864878?v=4",
        "events_url": "https://api.github.com/users/WXZhao7/events{/privacy}",
        "followers_url": "https://api.github.com/users/WXZhao7/followers",
        "following_url": "https://api.github.com/users/WXZhao7/following{/other_user}",
        "gists_url": "https://api.github.com/users/WXZhao7/gists{/gist_id}",
        "gravatar_id": "",
        "html_url": "https://github.com/WXZhao7",
        "id": 56864878,
        "login": "WXZhao7",
        "node_id": "MDQ6VXNlcjU2ODY0ODc4",
        "organizations_url": "https://api.github.com/users/WXZhao7/orgs",
        "received_events_url": "https://api.github.com/users/WXZhao7/received_events",
        "repos_url": "https://api.github.com/users/WXZhao7/repos",
        "site_admin": false,
        "starred_url": "https://api.github.com/users/WXZhao7/starred{/owner}{/repo}",
        "subscriptions_url": "https://api.github.com/users/WXZhao7/subscriptions",
        "type": "User",
        "url": "https://api.github.com/users/WXZhao7"
    }
}